Workbook
Name CarrierList: tCarriers[Carrier]
Name StatusList: tStatuses[Status]

Sheet Summary
A1: BUSINESS SUMMARY — ALL CHANNELS
A2: Combines the Inbound and Aged-Lead channels with shared overhead. Pulls live from the Inbound, Expenses, and Aged Lead Clients tabs.
A4: REVENUE
A5: Inbound — Paid | B5: =Inbound!B25 -> 8914.47
A6: Aged Leads — Paid | B6: =SUMIFS(tAgedClients[Amount],tAgedClients[Status],"Paid") -> 19913
A7: Total Paid Revenue | B7: =B5+B6 -> 28827.47
A8: Chargebacks | B8: =-(SUMIFS(tAgedClients[Amount],tAgedClients[Status],"Charged Back")+SUMIFS(tInboundClients[Paid],tInboundClients[Status],"Cancel")) -> -529
A9: Net Revenue | B9: =B7+B8 -> 28298.47
A11: EXPENSES
A12: Inbound — Lead Spend | B12: =Inbound!B11 -> 6690
A13: Aged Leads — Lead Spend | B13: =SUMIFS(tExpenses[Total],tExpenses[Category],"Lead Spend") -> 12063
A14: Monthly Tools | B14: =SUMIFS(tExpenses[Total],tExpenses[Category],"Monthly Tools") -> 2800
A15: Inbound Dials | B15: =SUMIFS(tExpenses[Total],tExpenses[Category],"Dials") -> 500
A16: Licensing (Exams + State) | B16: =SUMIFS(tExpenses[Total],tExpenses[Category],"Licensing") -> 2637
A17: Total Expenses | B17: =SUM(B12:B16) -> 24690
A19: PROFIT
A20: NET PROFIT (Combined) | B20: =B9-B17 -> 3608.47
A21: Inbound channel (Paid − Lead Spend) | B21: =B5-B12 -> 2224.47
A22: Aged-Lead channel (Paid − Lead Spend) | B22: =B6-B13 -> 7850
A23: Less: Shared Overhead (tools, dials, licensing) | B23: =-(B14+B15+B16) -> -5937
A24: Less: Chargebacks | B24: =B8 -> -529
A26: PIPELINE & POTENTIAL
A27: Inbound — In Pipe | B27: =Inbound!B26 -> 9052.665
A28: Aged Leads — In Pipe | B28: =SUMIFS(tAgedClients[Amount],tAgedClients[Status],"In Pipe") -> 2367
A29: Total Pipeline | B29: =B27+B28 -> 11419.665
A30: Potential (Net Profit + Pipeline) | B30: =B20+B29 -> 15028.135
A32: Note: the build-up (Inbound + Aged − Shared Overhead − Chargebacks) reconciles to NET PROFIT. The old Overall sheet excluded the inbound channel and did not deduct the $529 chargeback.

Sheet Inbound
A1: INBOUND LEADS — DASHBOARD
A2: Live summary — pulls from the Inbound Calls and Inbound Clients tabs. Add rows there and this updates automatically.
A4: Commission Advance % | B4: 0.75 | C4: ← input: % of annual premium carriers advance upfront
A6: LEAD ACTIVITY | D6: CARRIER BREAKDOWN
A7: Days Logged | B7: =COUNT(tInboundCalls[Date]) -> 26 | D7: Carrier | E7: Active Policies | F7: Active AP | G7: In Pipe
A8: Billable Calls | B8: =SUM(tInboundCalls[Billable Calls]) -> 120 | D8: {=IFERROR(INDEX(CarrierList,ROW()-ROW($D$7)),"")} -> MOO | E8: =IF($D8="","",COUNTIFS(tInboundClients[Carrier],$D8,tInboundClients[Status],"Active")) -> 4 | F8: =IF($D8="","",SUMIFS(tInboundClients[Annual Premium],tInboundClients[Carrier],$D8)) -> 3200 | G8: =IF($D8="","",SUMIFS(tInboundClients[In Pipe],tInboundClients[Carrier],$D8)) -> 1050.78
A9: Closes | B9: =SUM(tInboundCalls[Closes]) -> 43 | D9: {=IFERROR(INDEX(CarrierList,ROW()-ROW($D$7)),"")} -> Ethos | E9: =IF($D9="","",COUNTIFS(tInboundClients[Carrier],$D9,tInboundClients[Status],"Active")) -> 13 | F9: =IF($D9="","",SUMIFS(tInboundClients[Annual Premium],tInboundClients[Carrier],$D9)) -> 14318 | G9: =IF($D9="","",SUMIFS(tInboundClients[In Pipe],tInboundClients[Carrier],$D9)) -> 2426.6475
A10: Closing % | B10: =IFERROR(B9/B8,0) -> 0.35833333 | D10: {=IFERROR(INDEX(CarrierList,ROW()-ROW($D$7)),"")} -> Trans | E10: =IF($D10="","",COUNTIFS(tInboundClients[Carrier],$D10,tInboundClients[Status],"Active")) -> 8 | F10: =IF($D10="","",SUMIFS(tInboundClients[Annual Premium],tInboundClients[Carrier],$D10)) -> 5425 | G10: =IF($D10="","",SUMIFS(tInboundClients[In Pipe],tInboundClients[Carrier],$D10)) -> 1750.5
A11: Lead Spend | B11: =SUM(tInboundCalls[Lead Spend]) -> 6690 | D11: {=IFERROR(INDEX(CarrierList,ROW()-ROW($D$7)),"")} -> CoreBridge | E11: =IF($D11="","",COUNTIFS(tInboundClients[Carrier],$D11,tInboundClients[Status],"Active")) -> 6 | F11: =IF($D11="","",SUMIFS(tInboundClients[Annual Premium],tInboundClients[Carrier],$D11)) -> 4468 | G11: =IF($D11="","",SUMIFS(tInboundClients[In Pipe],tInboundClients[Carrier],$D11)) -> 1909.8
A12: Avg Cost / Call | B12: =IFERROR(B11/B8,0) -> 55.75 | D12: {=IFERROR(INDEX(CarrierList,ROW()-ROW($D$7)),"")} -> Americo | E12: =IF($D12="","",COUNTIFS(tInboundClients[Carrier],$D12,tInboundClients[Status],"Active")) -> 2 | F12: =IF($D12="","",SUMIFS(tInboundClients[Annual Premium],tInboundClients[Carrier],$D12)) -> 1717 | G12: =IF($D12="","",SUMIFS(tInboundClients[In Pipe],tInboundClients[Carrier],$D12)) -> 644.8125
D13: {=IFERROR(INDEX(CarrierList,ROW()-ROW($D$7)),"")} -> CICA | E13: =IF($D13="","",COUNTIFS(tInboundClients[Carrier],$D13,tInboundClients[Status],"Active")) -> 1 | F13: =IF($D13="","",SUMIFS(tInboundClients[Annual Premium],tInboundClients[Carrier],$D13)) -> 3387 | G13: =IF($D13="","",SUMIFS(tInboundClients[In Pipe],tInboundClients[Carrier],$D13)) -> 1270.125
A14: BOOK OF BUSINESS | D14: {=IFERROR(INDEX(CarrierList,ROW()-ROW($D$7)),"")} | E14: =IF($D14="","",COUNTIFS(tInboundClients[Carrier],$D14,tInboundClients[Status],"Active")) | F14: =IF($D14="","",SUMIFS(tInboundClients[Annual Premium],tInboundClients[Carrier],$D14)) | G14: =IF($D14="","",SUMIFS(tInboundClients[In Pipe],tInboundClients[Carrier],$D14))
A15: Total Clients | B15: =COUNTA(tInboundClients[Client]) -> 43 | D15: {=IFERROR(INDEX(CarrierList,ROW()-ROW($D$7)),"")} | E15: =IF($D15="","",COUNTIFS(tInboundClients[Carrier],$D15,tInboundClients[Status],"Active")) | F15: =IF($D15="","",SUMIFS(tInboundClients[Annual Premium],tInboundClients[Carrier],$D15)) | G15: =IF($D15="","",SUMIFS(tInboundClients[In Pipe],tInboundClients[Carrier],$D15))
A16: Active | B16: =COUNTIF(tInboundClients[Status],"Active") -> 34 | D16: {=IFERROR(INDEX(CarrierList,ROW()-ROW($D$7)),"")} | E16: =IF($D16="","",COUNTIFS(tInboundClients[Carrier],$D16,tInboundClients[Status],"Active")) | F16: =IF($D16="","",SUMIFS(tInboundClients[Annual Premium],tInboundClients[Carrier],$D16)) | G16: =IF($D16="","",SUMIFS(tInboundClients[In Pipe],tInboundClients[Carrier],$D16))
A17: Cancelled | B17: =COUNTIF(tInboundClients[Status],"Cancel") -> 9 | D17: Total | E17: =SUM(E8:E16) -> 34 | F17: =SUM(F8:F16) -> 32515 | G17: =SUM(G8:G16) -> 9052.665
A18: Cancel % | B18: =IFERROR(B17/(B16+B17),0) -> 0.20930233
A19: Active Annual Premium | B19: =SUM(tInboundClients[Annual Premium]) -> 32515
A20: Avg Premium (Active) | B20: =IFERROR(B19/B16,0) -> 956.32353
A21: Avg Monthly Premium | B21: =IFERROR(B20/12,0) -> 79.693627
A22: Avg Comp % (Active) | B22: =IFERROR(AVERAGEIF(tInboundClients[Status],"Active",tInboundClients[Comp %]),0) -> 0.83
A24: COMMISSIONS & RETURN
A25: Paid to Date | B25: =SUM(tInboundClients[Paid]) -> 8914.47
A26: In Pipe (outstanding) | B26: =SUM(tInboundClients[In Pipe]) -> 9052.665
A27: Total Expected (Paid + Pipe) | B27: =B25+B26 -> 17967.135
A28: ROI (Active AP / Lead Spend) | B28: =IFERROR(B19/B11,0) -> 4.8602392
A29: Profit (Paid − Lead Spend) | B29: =B25-B11 -> 2224.47
A30: Profit incl. Pipe | B30: =B25+B26-B11 -> 11277.135

Sheet Inbound Calls
A1: Date | B1: Billable Calls | C1: Closes | D1: Closing % | E1: Lead Spend | F1: Cost / Call
A2: 46141 | B2: 3 | C2: 2 | D2: =IF(B2=0,0,C2/B2) -> 0.66666667 | E2: 150 | F2: =IF(B2=0,0,E2/B2) -> 50
A3: 46142 | B3: 3 | C3: 2 | D3: =IF(B3=0,0,C3/B3) -> 0.66666667 | E3: 150 | F3: =IF(B3=0,0,E3/B3) -> 50
A4: 46143 | B4: 3 | C4: 1 | D4: =IF(B4=0,0,C4/B4) -> 0.33333333 | E4: 150 | F4: =IF(B4=0,0,E4/B4) -> 50
A5: 46144 | B5: 2 | C5: 0 | D5: =IF(B5=0,0,C5/B5) -> 0 | E5: 100 | F5: =IF(B5=0,0,E5/B5) -> 50
A6: 46146 | B6: 2 | C6: 1 | D6: =IF(B6=0,0,C6/B6) -> 0.5 | E6: 140 | F6: =IF(B6=0,0,E6/B6) -> 70
A7: 46147 | B7: 4 | C7: 1 | D7: =IF(B7=0,0,C7/B7) -> 0.25 | E7: 270 | F7: =IF(B7=0,0,E7/B7) -> 67.5
A8: 46148 | B8: 3 | C8: 2 | D8: =IF(B8=0,0,C8/B8) -> 0.66666667 | E8: 210 | F8: =IF(B8=0,0,E8/B8) -> 70
A9: 46149 | B9: 5 | C9: 4 | D9: =IF(B9=0,0,C9/B9) -> 0.8 | E9: 435 | F9: =IF(B9=0,0,E9/B9) -> 87
A10: 46150 | B10: 6 | C10: 1 | D10: =IF(B10=0,0,C10/B10) -> 0.16666667 | E10: 410 | F10: =IF(B10=0,0,E10/B10) -> 68.333333
A11: 46153 | B11: 6 | C11: 2 | D11: =IF(B11=0,0,C11/B11) -> 0.33333333 | E11: 475 | F11: =IF(B11=0,0,E11/B11) -> 79.166667
A12: 46154 | B12: 6 | C12: 2 | D12: =IF(B12=0,0,C12/B12) -> 0.33333333 | E12: 350 | F12: =IF(B12=0,0,E12/B12) -> 58.333333
A13: 46160 | B13: 5 | C13: 2 | D13: =IF(B13=0,0,C13/B13) -> 0.4 | E13: 250 | F13: =IF(B13=0,0,E13/B13) -> 50
... A27: 46185 | B27: 3 | C27: 1 | D27: =IF(B27=0,0,C27/B27) -> 0.33333333 | E27: 150 | F27: =IF(B27=0,0,E27/B27) -> 50

Sheet Inbound Clients
A1: Client | B1: Effective | C1: Carrier | D1: Status | E1: Annual Premium | F1: Comp % | G1: Paid | H1: In Pipe
A2: John Homan | B2: 46157 | C2: MOO | D2: Cancel | F2: 0.86 | H2: =IF(AND(D2="Active",OR(G2=0,G2="")),E2*F2*Inbound!$B$4,0) -> 0
A3: Alice Jackson | B3: 46171 | C3: Ethos | D3: Cancel | F3: 0.87 | H3: =IF(AND(D3="Active",OR(G3=0,G3="")),E3*F3*Inbound!$B$4,0) -> 0
A4: Ila Ibarra | B4: 46144 | C4: Trans | D4: Active | E4: 353 | F4: 1 | H4: =IF(AND(D4="Active",OR(G4=0,G4="")),E4*F4*Inbound!$B$4,0) -> 264.75
A5: Katherine Torres | B5: 46169 | C5: MOO | D5: Cancel | F5: 0.86 | H5: =IF(AND(D5="Active",OR(G5=0,G5="")),E5*F5*Inbound!$B$4,0) -> 0
A6: Catherine Mills | B6: 46151 | C6: Ethos | D6: Active | E6: 1128 | F6: 0.87 | G6: 355 | H6: =IF(AND(D6="Active",OR(G6=0,G6="")),E6*F6*Inbound!$B$4,0) -> 0
A7: Kevin Bolton | B7: 46146 | C7: Ethos | D7: Active | E7: 1154 | F7: 0.87 | G7: 662 | H7: =IF(AND(D7="Active",OR(G7=0,G7="")),E7*F7*Inbound!$B$4,0) -> 0
A8: Humbert Jones | B8: 46147 | C8: Ethos | D8: Cancel | F8: 0.87 | H8: =IF(AND(D8="Active",OR(G8=0,G8="")),E8*F8*Inbound!$B$4,0) -> 0
A9: Jesse Hill | B9: 46148 | C9: Ethos | D9: Active | E9: 2428 | F9: 0.87 | G9: 1450 | H9: =IF(AND(D9="Active",OR(G9=0,G9="")),E9*F9*Inbound!$B$4,0) -> 0
A10: Vincent West | B10: 46176 | C10: Ethos | D10: Active | E10: 1042 | F10: 0.87 | G10: 592.47 | H10: =IF(AND(D10="Active",OR(G10=0,G10="")),E10*F10*Inbound!$B$4,0) -> 0
A11: Jacinta Mitchell | B11: 46153 | C11: CoreBridge | D11: Active | E11: 740 | F11: 0.6 | H11: =IF(AND(D11="Active",OR(G11=0,G11="")),E11*F11*Inbound!$B$4,0) -> 333
A12: Edwin Esturiene | B12: 46154 | C12: MOO | D12: Active | E12: 888 | F12: 0.86 | G12: 574 | H12: =IF(AND(D12="Active",OR(G12=0,G12="")),E12*F12*Inbound!$B$4,0) -> 0
A13: Carldon Hardin | B13: 46160 | C13: Trans | D13: Cancel | F13: 0.86 | H13: =IF(AND(D13="Active",OR(G13=0,G13="")),E13*F13*Inbound!$B$4,0) -> 0
A14: Terry Altom | B14: 46161 | C14: Ethos | D14: Active | E14: 837 | F14: 0.87 | G14: 465 | H14: =IF(AND(D14="Active",OR(G14=0,G14="")),E14*F14*Inbound!$B$4,0) -> 0
A15: Tonia Woods | B15: 46157 | C15: Trans | D15: Active | E15: 865 | F15: 1 | G15: 649 | H15: =IF(AND(D15="Active",OR(G15=0,G15="")),E15*F15*Inbound!$B$4,0) -> 0
A16: Dan Sheteron | B16: 46176 | C16: Americo | D16: Active | E16: 812 | F16: 0.95 | G16: 579 | H16: =IF(AND(D16="Active",OR(G16=0,G16="")),E16*F16*Inbound!$B$4,0) -> 0
A17: Russell Bush | B17: 46164 | C17: Ethos | D17: Active | E17: 1713 | F17: 0.87 | G17: 1008 | H17: =IF(AND(D17="Active",OR(G17=0,G17="")),E17*F17*Inbound!$B$4,0) -> 0
A18: Stephanie Pree | B18: 46176 | C18: Trans | D18: Active | E18: 700 | F18: 1 | H18: =IF(AND(D18="Active",OR(G18=0,G18="")),E18*F18*Inbound!$B$4,0) -> 525
A19: Cheri Rangitsch | B19: 46154 | C19: MOO | D19: Active | E19: 464 | F19: 0.86 | G19: 297 | H19: =IF(AND(D19="Active",OR(G19=0,G19="")),E19*F19*Inbound!$B$4,0) -> 0
A20: Martin Wollemberg | B20: 46188 | C20: MOO | D20: Cancel | F20: 0.86 | H20: =IF(AND(D20="Active",OR(G20=0,G20="")),E20*F20*Inbound!$B$4,0) -> 0
A21: Kathryn Holland | B21: 46176 | C21: Ethos | D21: Active | E21: 832 | F21: 0.87 | G21: 462 | H21: =IF(AND(D21="Active",OR(G21=0,G21="")),E21*F21*Inbound!$B$4,0) -> 0
A22: Anita Kirkwood | B22: 46176 | C22: Ethos | D22: Active | E22: 685 | F22: 0.87 | G22: 205 | H22: =IF(AND(D22="Active",OR(G22=0,G22="")),E22*F22*Inbound!$B$4,0) -> 0
A23: Jeanne Hahn | B23: 46176 | C23: Ethos | D23: Active | E23: 780 | F23: 0.87 | G23: 430 | H23: =IF(AND(D23="Active",OR(G23=0,G23="")),E23*F23*Inbound!$B$4,0) -> 0
A24: Loretta Mack | B24: 46176 | C24: Ethos | D24: Cancel | F24: 0.87 | H24: =IF(AND(D24="Active",OR(G24=0,G24="")),E24*F24*Inbound!$B$4,0) -> 0
A25: Susan Witt | B25: 46169 | C25: Trans | D25: Active | E25: 901 | F25: 1 | G25: 698 | H25: =IF(AND(D25="Active",OR(G25=0,G25="")),E25*F25*Inbound!$B$4,0) -> 0
A26: Kelly Pettit | B26: 46163 | C26: Ethos | D26: Cancel | F26: 0.87 | H26: =IF(AND(D26="Active",OR(G26=0,G26="")),E26*F26*Inbound!$B$4,0) -> 0
A27: Thomas Hill | B27: 46178 | C27: CICA | D27: Active | E27: 3387 | F27: 0.5 | H27: =IF(AND(D27="Active",OR(G27=0,G27="")),E27*F27*Inbound!$B$4,0) -> 1270.125
A28: Carol Garneau | B28: 46174 | C28: Trans | D28: Active | E28: 675 | H28: =IF(AND(D28="Active",OR(G28=0,G28="")),E28*F28*Inbound!$B$4,0) -> 0
A29: Winfred Cortimiglia | B29: 46190 | C29: Ethos | D29: Active | E29: 952 | F29: 0.87 | H29: =IF(AND(D29="Active",OR(G29=0,G29="")),E29*F29*Inbound!$B$4,0) -> 621.18
A30: Audrey Patrick | B30: 46204 | C30: CoreBridge | D30: Active | E30: 371 | F30: 0.6 | H30: =IF(AND(D30="Active",OR(G30=0,G30="")),E30*F30*Inbound!$B$4,0) -> 166.95
A31: Tony Moldanado | B31: 46188 | C31: Trans | D31: Active | E31: 866 | F31: 1 | H31: =IF(AND(D31="Active",OR(G31=0,G31="")),E31*F31*Inbound!$B$4,0) -> 649.5
A32: Sylvia Bell | B32: 46188 | C32: CoreBridge | D32: Active | E32: 949 | F32: 0.6 | H32: =IF(AND(D32="Active",OR(G32=0,G32="")),E32*F32*Inbound!$B$4,0) -> 427.05
A33: Sandra Bishop | B33: 46183 | C33: Trans | D33: Active | E33: 650 | F33: 1 | G33: 488 | H33: =IF(AND(D33="Active",OR(G33=0,G33="")),E33*F33*Inbound!$B$4,0) -> 0
A34: Kimberley Purser | B34: 46206 | C34: CoreBridge | D34: Active | E34: 537 | F34: 0.6 | H34: =IF(AND(D34="Active",OR(G34=0,G34="")),E34*F34*Inbound!$B$4,0) -> 241.65
A35: Ramel Rodriguez | B35: 46191 | C35: CoreBridge | D35: Active | E35: 527 | F35: 0.6 | H35: =IF(AND(D35="Active",OR(G35=0,G35="")),E35*F35*Inbound!$B$4,0) -> 237.15
A36: Aurelio Anchondo | B36: 46207 | C36: Americo | D36: Active | E36: 905 | F36: 0.95 | H36: =IF(AND(D36="Active",OR(G36=0,G36="")),E36*F36*Inbound!$B$4,0) -> 644.8125
A37: Jessie Riddle | B37: 46204 | C37: Ethos | D37: Active | E37: 827 | F37: 0.87 | H37: =IF(AND(D37="Active",OR(G37=0,G37="")),E37*F37*Inbound!$B$4,0) -> 539.6175
A38: Lucinda Murphy-Lacy | B38: 46204 | C38: MOO | D38: Active | E38: 1124 | F38: 0.86 | H38: =IF(AND(D38="Active",OR(G38=0,G38="")),E38*F38*Inbound!$B$4,0) -> 724.98
A39: Hazellani Davis | B39: 46204 | C39: Trans | D39: Active | E39: 415 | F39: 1 | H39: =IF(AND(D39="Active",OR(G39=0,G39="")),E39*F39*Inbound!$B$4,0) -> 311.25
A40: Joyce Williams | B40: 46198 | C40: Ethos | D40: Active | E40: 1235 | F40: 0.87 | H40: =IF(AND(D40="Active",OR(G40=0,G40="")),E40*F40*Inbound!$B$4,0) -> 805.8375
...

Sheet Aged Lead Clients
A1: Client | B1: Status | C1: Amount
A2: Shirley Dawson | B2: Paid | C2: 1153
A3: Maria Torres | B3: Paid | C3: 1115
A4: Stacey Zimmer | B4: Paid | C4: 500
A5: Debbie Hudson | B5: Paid | C5: 753
A6: Ronald Crowder | B6: Paid | C6: 338
A7: Julia Serrano | B7: Paid | C7: 611
A8: Jason Conary | B8: Paid | C8: 839
A9: Laura Conary | B9: Paid | C9: 326
A10: Robert Liddell | B10: Paid | C10: 3000
A11: Michael Perkins | B11: Paid | C11: 561
A12: Samuel Weldon | B12: Paid | C12: 873
A13: Holly McCready | B13: Paid | C13: 432
... A28: Donna Isaac | B28: Charged Back | C28: 529

Sheet Chargebacks
A1: CHARGEBACKS
A2: Auto-updates. Any inbound client set to "Cancel" that was already paid appears here, alongside aged-lead chargebacks. The total feeds the Chargebacks line on the Summary.
A4: TOTAL CHARGEBACKS | B4: =SUMIFS(tInboundClients[Paid],tInboundClients[Status],"Cancel")+SUMIFS(tAgedClients[Amount],tAgedClients[Status],"Charged Back") -> 529
A6: Cancelled Inbound Clients | D6: Aged-Lead Chargebacks
A7: Client | B7: Charged Back | D7: Client | E7: Amount
A8: {=_xlfn._xlws.FILTER(_xlfn.HSTACK(tInboundClients[Client],tInboundClients[Paid]),(tInboundClients[Status]="Cancel")*(tInboundClients[Paid]>0),"None yet")} -> None yet | D8: {=_xlfn._xlws.FILTER(_xlfn.HSTACK(tAgedClients[Client],tAgedClients[Amount]),tAgedClients[Status]="Charged Back","None")} -> Donna Isaac | E8: 529

Sheet Expenses
A1: Category | B1: Item | C1: Amount | D1: Months | E1: Total
A2: Lead Spend | B2: Aged Leads | C2: 12063 | D2: 1 | E2: =C2*D2 -> 12063
A3: Monthly Tools | B3: Office Space | C3: 500 | D3: 4 | E3: =C3*D3 -> 2000
A4: Monthly Tools | B4: WAVV | C4: 100 | D4: 4 | E4: =C4*D4 -> 400
A5: Monthly Tools | B5: CRM | C5: 50 | D5: 4 | E5: =C5*D5 -> 200
A6: Monthly Tools | B6: Numbers | C6: 50 | D6: 4 | E6: =C6*D6 -> 200
A7: Dials | B7: Inbound Dials | C7: 500 | D7: 1 | E7: =C7*D7 -> 500
A8: Licensing | B8: Exams + Courses | C8: 1000 | D8: 1 | E8: =C8*D8 -> 1000
A9: Licensing | B9: Texas | C9: 50 | D9: 1 | E9: =C9*D9 -> 50
A10: Licensing | B10: Ohio | C10: 10 | D10: 1 | E10: =C10*D10 -> 10
A11: Licensing | B11: South Dakota | C11: 30 | D11: 1 | E11: =C11*D11 -> 30
A12: Licensing | B12: South Carolina | C12: 25 | D12: 1 | E12: =C12*D12 -> 25
A13: Licensing | B13: Maine | C13: 55 | D13: 1 | E13: =C13*D13 -> 55
... A32: Licensing | B32: Maryland | C32: 60 | D32: 1 | E32: =C32*D32 -> 60

Sheet Lists
A1: Reference Lists
A2: Add new carriers at the bottom of this list — they flow to the Inbound Clients dropdown and the Inbound carrier breakdown automatically.
A4: Carrier | C4: Status
A5: MOO | C5: Active
A6: Ethos | C6: Cancel
A7: Trans
A8: CoreBridge
A9: Americo
A10: CICA
